<?xml version="1.0" encoding="UTF-8"?><testsuite name="nosetests" tests="12" errors="0" failures="2" skip="0"><testcase classname="todo.tests.TestCreateTodoItems" name="test_item_has_correct_title" time="0.196"></testcase><testcase classname="todo.tests.TestCreateTodoItems" name="test_item_was_created" time="0.009"></testcase><testcase classname="todo.tests.TestCreateTodoItems" name="test_received_201_created_status_code" time="0.008"></testcase><testcase classname="todo.tests.TestCreateTodoItems" name="test_received_location_header_hyperlink" time="0.013"></testcase><testcase classname="todo.tests.TestDeleteAllTodoItem" name="test_all_items_were_deleted" time="0.032"><failure type="exceptions.AssertionError" message="2 != 0"><![CDATA[Traceback (most recent call last):
  File "/usr/local/Cellar/python/2.7.13/Frameworks/Python.framework/Versions/2.7/lib/python2.7/unittest/case.py", line 329, in run
    testMethod()
  File "/Users/groberts/cd-docker-ansible/src/todo/tests.py", line 86, in test_all_items_were_deleted
    self.assertEqual(TodoItem.objects.count(),0)
  File "/usr/local/Cellar/python/2.7.13/Frameworks/Python.framework/Versions/2.7/lib/python2.7/unittest/case.py", line 513, in assertEqual
    assertion_func(first, second, msg=msg)
  File "/usr/local/Cellar/python/2.7.13/Frameworks/Python.framework/Versions/2.7/lib/python2.7/unittest/case.py", line 506, in _baseAssertEqual
    raise self.failureException(msg)
AssertionError: 2 != 0
]]></failure></testcase><testcase classname="todo.tests.TestDeleteAllTodoItem" name="test_received_204_no_content_status_code" time="0.025"><failure type="exceptions.AssertionError" message="405 != 204"><![CDATA[Traceback (most recent call last):
  File "/usr/local/Cellar/python/2.7.13/Frameworks/Python.framework/Versions/2.7/lib/python2.7/unittest/case.py", line 329, in run
    testMethod()
  File "/Users/groberts/cd-docker-ansible/src/todo/tests.py", line 83, in test_received_204_no_content_status_code
    self.assertEqual(self.response.status_code, status.HTTP_204_NO_CONTENT)
  File "/usr/local/Cellar/python/2.7.13/Frameworks/Python.framework/Versions/2.7/lib/python2.7/unittest/case.py", line 513, in assertEqual
    assertion_func(first, second, msg=msg)
  File "/usr/local/Cellar/python/2.7.13/Frameworks/Python.framework/Versions/2.7/lib/python2.7/unittest/case.py", line 506, in _baseAssertEqual
    raise self.failureException(msg)
AssertionError: 405 != 204
]]></failure></testcase><testcase classname="todo.tests.TestDeleteTodoItem" name="test_item_was_deleted" time="0.024"></testcase><testcase classname="todo.tests.TestDeleteTodoItem" name="test_received_204_no_content_status_code" time="0.023"></testcase><testcase classname="todo.tests.TestPatchTodoItem" name="test_item_was_patched" time="0.034"></testcase><testcase classname="todo.tests.TestPatchTodoItem" name="test_received_200_ok_status_code" time="0.026"></testcase><testcase classname="todo.tests.TestUpdateTodoItem" name="test_item_was_updated" time="0.028"></testcase><testcase classname="todo.tests.TestUpdateTodoItem" name="test_received_200_ok_status_code" time="0.027"></testcase></testsuite>